[2021-10-21 18:48:40,203] {taskinstance.py:877} INFO - Dependencies all met for <TaskInstance: Fire_Incidents.Check_credentials 2021-10-21T18:48:39.337510+00:00 [queued]>
[2021-10-21 18:48:40,214] {taskinstance.py:877} INFO - Dependencies all met for <TaskInstance: Fire_Incidents.Check_credentials 2021-10-21T18:48:39.337510+00:00 [queued]>
[2021-10-21 18:48:40,215] {taskinstance.py:1068} INFO - 
--------------------------------------------------------------------------------
[2021-10-21 18:48:40,215] {taskinstance.py:1069} INFO - Starting attempt 1 of 2
[2021-10-21 18:48:40,215] {taskinstance.py:1070} INFO - 
--------------------------------------------------------------------------------
[2021-10-21 18:48:40,221] {taskinstance.py:1089} INFO - Executing <Task(PythonOperator): Check_credentials> on 2021-10-21T18:48:39.337510+00:00
[2021-10-21 18:48:40,225] {standard_task_runner.py:52} INFO - Started process 54 to run task
[2021-10-21 18:48:40,227] {standard_task_runner.py:76} INFO - Running: ['airflow', 'tasks', 'run', 'Fire_Incidents', 'Check_credentials', '2021-10-21T18:48:39.337510+00:00', '--job-id', '5', '--pool', 'default_pool', '--raw', '--subdir', 'DAGS_FOLDER/tutorial.py', '--cfg-path', '/tmp/tmpp_mzjp76', '--error-file', '/tmp/tmpr7y958o0']
[2021-10-21 18:48:40,228] {standard_task_runner.py:77} INFO - Job 5: Subtask Check_credentials
[2021-10-21 18:48:40,256] {logging_mixin.py:104} INFO - Running <TaskInstance: Fire_Incidents.Check_credentials 2021-10-21T18:48:39.337510+00:00 [running]> on host 8ad12bb33883
[2021-10-21 18:48:40,284] {taskinstance.py:1283} INFO - Exporting the following env vars:
AIRFLOW_CTX_DAG_EMAIL=airflow@example.com
AIRFLOW_CTX_DAG_OWNER=airflow
AIRFLOW_CTX_DAG_ID=Fire_Incidents
AIRFLOW_CTX_TASK_ID=Check_credentials
AIRFLOW_CTX_EXECUTION_DATE=2021-10-21T18:48:39.337510+00:00
AIRFLOW_CTX_DAG_RUN_ID=manual__2021-10-21T18:48:39.337510+00:00
[2021-10-21 18:48:40,285] {logging_mixin.py:104} INFO - The Connection is:
[2021-10-21 18:48:40,285] {logging_mixin.py:104} INFO - {'region': 'us-west-2', 'access_token': 'FwoGZXIvYXdzEGoaDJReBSrOlfC09PeS7SKGAZYj8TJ17+aoC63as7iG5hoBR6sd977vDzKvgWTMf7J1mFWT3CBpgmPbT2hsPhjLMqX6qepk+EEKQgPTWaApYSUDed6XjBkZHt1mKVAH8TpjdS9+8MgDcEZJbapU8wizUZPzy0Yer2ot+23uFsHEWmWBJ9Oaf/mtLOmzdf/1uz3TsCOcbXRIKMvhwosGMij2XzeTshWnu45hR8qAGzfLMl4Zqr9PrjEI3oI7wOhJJWhks7mxcYAB'}
[2021-10-21 18:48:40,285] {taskinstance.py:1482} ERROR - Task failed with exception
Traceback (most recent call last):
  File "/home/airflow/.local/lib/python3.6/site-packages/airflow/models/taskinstance.py", line 1138, in _run_raw_task
    self._prepare_and_execute_task_with_callbacks(context, task)
  File "/home/airflow/.local/lib/python3.6/site-packages/airflow/models/taskinstance.py", line 1311, in _prepare_and_execute_task_with_callbacks
    result = self._execute_task(context, task_copy)
  File "/home/airflow/.local/lib/python3.6/site-packages/airflow/models/taskinstance.py", line 1341, in _execute_task
    result = task_copy.execute(context=context)
  File "/home/airflow/.local/lib/python3.6/site-packages/airflow/operators/python.py", line 117, in execute
    return_value = self.execute_callable()
  File "/home/airflow/.local/lib/python3.6/site-packages/airflow/operators/python.py", line 128, in execute_callable
    return self.python_callable(*self.op_args, **self.op_kwargs)
  File "/opt/airflow/dags/tutorial.py", line 88, in check
    print(info["region_name"])
KeyError: 'region_name'
[2021-10-21 18:48:40,286] {taskinstance.py:1532} INFO - Marking task as UP_FOR_RETRY. dag_id=Fire_Incidents, task_id=Check_credentials, execution_date=20211021T184839, start_date=20211021T184840, end_date=20211021T184840
[2021-10-21 18:48:40,320] {local_task_job.py:146} INFO - Task exited with return code 1
