[2021-10-21 18:50:10,771] {taskinstance.py:877} INFO - Dependencies all met for <TaskInstance: Fire_Incidents.Step_Function 2021-10-21T18:50:09.074331+00:00 [queued]>
[2021-10-21 18:50:10,785] {taskinstance.py:877} INFO - Dependencies all met for <TaskInstance: Fire_Incidents.Step_Function 2021-10-21T18:50:09.074331+00:00 [queued]>
[2021-10-21 18:50:10,785] {taskinstance.py:1068} INFO - 
--------------------------------------------------------------------------------
[2021-10-21 18:50:10,786] {taskinstance.py:1069} INFO - Starting attempt 1 of 2
[2021-10-21 18:50:10,786] {taskinstance.py:1070} INFO - 
--------------------------------------------------------------------------------
[2021-10-21 18:50:10,792] {taskinstance.py:1089} INFO - Executing <Task(PythonOperator): Step_Function> on 2021-10-21T18:50:09.074331+00:00
[2021-10-21 18:50:10,797] {standard_task_runner.py:52} INFO - Started process 58 to run task
[2021-10-21 18:50:10,799] {standard_task_runner.py:76} INFO - Running: ['airflow', 'tasks', 'run', 'Fire_Incidents', 'Step_Function', '2021-10-21T18:50:09.074331+00:00', '--job-id', '7', '--pool', 'default_pool', '--raw', '--subdir', 'DAGS_FOLDER/tutorial.py', '--cfg-path', '/tmp/tmp9jg0f133', '--error-file', '/tmp/tmpxd371azr']
[2021-10-21 18:50:10,800] {standard_task_runner.py:77} INFO - Job 7: Subtask Step_Function
[2021-10-21 18:50:10,830] {logging_mixin.py:104} INFO - Running <TaskInstance: Fire_Incidents.Step_Function 2021-10-21T18:50:09.074331+00:00 [running]> on host 8ad12bb33883
[2021-10-21 18:50:10,860] {taskinstance.py:1283} INFO - Exporting the following env vars:
AIRFLOW_CTX_DAG_EMAIL=airflow@example.com
AIRFLOW_CTX_DAG_OWNER=airflow
AIRFLOW_CTX_DAG_ID=Fire_Incidents
AIRFLOW_CTX_TASK_ID=Step_Function
AIRFLOW_CTX_EXECUTION_DATE=2021-10-21T18:50:09.074331+00:00
AIRFLOW_CTX_DAG_RUN_ID=manual__2021-10-21T18:50:09.074331+00:00
[2021-10-21 18:50:12,107] {taskinstance.py:1482} ERROR - Task failed with exception
Traceback (most recent call last):
  File "/home/airflow/.local/lib/python3.6/site-packages/airflow/models/taskinstance.py", line 1138, in _run_raw_task
    self._prepare_and_execute_task_with_callbacks(context, task)
  File "/home/airflow/.local/lib/python3.6/site-packages/airflow/models/taskinstance.py", line 1311, in _prepare_and_execute_task_with_callbacks
    result = self._execute_task(context, task_copy)
  File "/home/airflow/.local/lib/python3.6/site-packages/airflow/models/taskinstance.py", line 1341, in _execute_task
    result = task_copy.execute(context=context)
  File "/home/airflow/.local/lib/python3.6/site-packages/airflow/operators/python.py", line 117, in execute
    return_value = self.execute_callable()
  File "/home/airflow/.local/lib/python3.6/site-packages/airflow/operators/python.py", line 128, in execute_callable
    return self.python_callable(*self.op_args, **self.op_kwargs)
  File "/opt/airflow/dags/tutorial.py", line 61, in aws_step_function
    stateMachineArn=stateMachineArn
  File "/home/airflow/.local/lib/python3.6/site-packages/botocore/client.py", line 357, in _api_call
    return self._make_api_call(operation_name, kwargs)
  File "/home/airflow/.local/lib/python3.6/site-packages/botocore/client.py", line 676, in _make_api_call
    raise error_class(parsed_response, operation_name)
botocore.exceptions.ClientError: An error occurred (UnrecognizedClientException) when calling the StartExecution operation: The security token included in the request is invalid.
[2021-10-21 18:50:12,112] {taskinstance.py:1532} INFO - Marking task as UP_FOR_RETRY. dag_id=Fire_Incidents, task_id=Step_Function, execution_date=20211021T185009, start_date=20211021T185010, end_date=20211021T185012
[2021-10-21 18:50:12,177] {local_task_job.py:146} INFO - Task exited with return code 1
